Traceback (most recent call last):
  File "/usr/local/lib/python3.9/site-packages/jupyter_cache/executors/utils.py", line 51, in single_nb_execution
    executenb(
  File "/usr/local/lib/python3.9/site-packages/nbclient/client.py", line 1117, in execute
    return NotebookClient(nb=nb, resources=resources, km=km, **kwargs).execute()
  File "/usr/local/lib/python3.9/site-packages/nbclient/util.py", line 78, in wrapped
    return just_run(coro(*args, **kwargs))
  File "/usr/local/lib/python3.9/site-packages/nbclient/util.py", line 57, in just_run
    return loop.run_until_complete(coro)
  File "/usr/local/Cellar/python@3.9/3.9.6/Frameworks/Python.framework/Versions/3.9/lib/python3.9/asyncio/base_events.py", line 642, in run_until_complete
    return future.result()
  File "/usr/local/lib/python3.9/site-packages/nbclient/client.py", line 558, in async_execute
    await self.async_execute_cell(
  File "/usr/local/lib/python3.9/site-packages/nbclient/client.py", line 862, in async_execute_cell
    self._check_raise_for_error(cell, exec_reply)
  File "/usr/local/lib/python3.9/site-packages/nbclient/client.py", line 765, in _check_raise_for_error
    raise CellExecutionError.from_cell_and_msg(cell, exec_reply_content)
nbclient.exceptions.CellExecutionError: An error occurred while executing the following cell:
------------------
x = np.load('/Users/mcmahonmc/Github/machine-learning-2021/final/actigraphy_data.npy')
print('actigraphy data')
print(x.shape)

actdf = pd.read_csv('/Users/mcmahonmc/Github/machine-learning-2021/final/actigraphy_data_df.csv')
print('actigraphy df')
print(actdf.shape)

targets = pd.read_csv('/Users/mcmahonmc/Github/machine-learning-2021/final/target_data.csv')
print('targets')
print(targets.shape)

targets[:5]
------------------

[0;31m---------------------------------------------------------------------------[0m
[0;31mFileNotFoundError[0m                         Traceback (most recent call last)
[0;32m/var/folders/ld/qzxjl7f92_5gzy756sfjkjfh0000gn/T/ipykernel_4163/3363168093.py[0m in [0;36m<module>[0;34m[0m
[0;32m----> 1[0;31m [0mx[0m [0;34m=[0m [0mnp[0m[0;34m.[0m[0mload[0m[0;34m([0m[0;34m'/Users/mcmahonmc/Github/machine-learning-2021/final/actigraphy_data.npy'[0m[0;34m)[0m[0;34m[0m[0;34m[0m[0m
[0m[1;32m      2[0m [0mprint[0m[0;34m([0m[0;34m'actigraphy data'[0m[0;34m)[0m[0;34m[0m[0;34m[0m[0m
[1;32m      3[0m [0mprint[0m[0;34m([0m[0mx[0m[0;34m.[0m[0mshape[0m[0;34m)[0m[0;34m[0m[0;34m[0m[0m
[1;32m      4[0m [0;34m[0m[0m
[1;32m      5[0m [0mactdf[0m [0;34m=[0m [0mpd[0m[0;34m.[0m[0mread_csv[0m[0;34m([0m[0;34m'/Users/mcmahonmc/Github/machine-learning-2021/final/actigraphy_data_df.csv'[0m[0;34m)[0m[0;34m[0m[0;34m[0m[0m

[0;32m/usr/local/lib/python3.9/site-packages/numpy/lib/npyio.py[0m in [0;36mload[0;34m(file, mmap_mode, allow_pickle, fix_imports, encoding)[0m
[1;32m    415[0m             [0mown_fid[0m [0;34m=[0m [0;32mFalse[0m[0;34m[0m[0;34m[0m[0m
[1;32m    416[0m         [0;32melse[0m[0;34m:[0m[0;34m[0m[0;34m[0m[0m
[0;32m--> 417[0;31m             [0mfid[0m [0;34m=[0m [0mstack[0m[0;34m.[0m[0menter_context[0m[0;34m([0m[0mopen[0m[0;34m([0m[0mos_fspath[0m[0;34m([0m[0mfile[0m[0;34m)[0m[0;34m,[0m [0;34m"rb"[0m[0;34m)[0m[0;34m)[0m[0;34m[0m[0;34m[0m[0m
[0m[1;32m    418[0m             [0mown_fid[0m [0;34m=[0m [0;32mTrue[0m[0;34m[0m[0;34m[0m[0m
[1;32m    419[0m [0;34m[0m[0m

[0;31mFileNotFoundError[0m: [Errno 2] No such file or directory: '/Users/mcmahonmc/Github/machine-learning-2021/final/actigraphy_data.npy'
FileNotFoundError: [Errno 2] No such file or directory: '/Users/mcmahonmc/Github/machine-learning-2021/final/actigraphy_data.npy'

